<?xml version="1.0" encoding="utf-8"?>
<robot name="Matrix_bot">
  <link name="base_link">
    <inertial>
      <origin xyz="0 0 0" rpy="0 0 0"/>
      <mass value="2.0"/>
      <inertia ixx="0.02" ixy="0.0" ixz="0.0"
               iyy="0.02" iyz="0.0"
               izz="0.03"/>
    </inertial>
    <visual>
      <origin xyz="0 0 0" rpy="0 0 0"/>
      <geometry>
        <mesh filename="package://matrix_bot/meshes/base_link.STL"/>
      </geometry>
      <material name="">
        <color rgba="0 0 0.5 1"/>
      </material>
    </visual>
    <collision>
      <origin xyz="0 0 0" rpy="0 0 0"/>
      <geometry>
        <mesh filename="package://matrix_bot/meshes/base_link.STL"/>
      </geometry>
    </collision>
  </link>

  <link name="left_wheel">
    <inertial>
      <origin xyz="0 0 0" rpy="0 0 0"/>
      <mass value="0.2"/>
      <inertia ixx="0.001" ixy="0.0" ixz="0.0"
               iyy="0.001" iyz="0.0"
               izz="0.0015"/>
    </inertial>
    <visual>
      <origin xyz="0 0 0" rpy="0 0 0"/>
      <geometry>
        <mesh filename="package://matrix_bot/meshes/left_wheel.STL"/>
      </geometry>
      <material name="">
        <color rgba="0 0 0 1"/>
      </material>
    </visual>
    <collision>
      <origin xyz="0 0 0" rpy="0 0 0"/>
      <geometry>
        <mesh filename="package://matrix_bot/meshes/left_wheel.STL"/>
      </geometry>
    </collision>
  </link>

  <joint name="left_wheel_joint" type="continuous">
    <origin xyz="0.15278 -0.19761 0.07511" rpy="1.5708 1.2605 0"/>
    <parent link="base_link"/>
    <child link="left_wheel"/>
    <axis xyz="0 0 1"/>
  </joint>

  <link name="right_wheel">
    <inertial>
      <origin xyz="0 0 0" rpy="0 0 0"/>
      <mass value="0.2"/>
      <inertia ixx="0.001" ixy="0.0" ixz="0.0"
               iyy="0.001" iyz="0.0"
               izz="0.0015"/>
    </inertial>
    <visual>
      <origin xyz="0 0 0" rpy="0 0 0"/>
      <geometry>
        <mesh filename="package://matrix_bot/meshes/right_wheel.STL"/>
      </geometry>
      <material name="">
        <color rgba="0 0 0 1"/>
      </material>
    </visual>
    <collision>
      <origin xyz="0 0 0" rpy="0 0 0"/>
      <geometry>
        <mesh filename="package://matrix_bot/meshes/right_wheel.STL"/>
      </geometry>
    </collision>
  </link>

  <joint name="right_wheel_joint" type="continuous">
    <origin xyz="0.15278 -0.082606 0.07511" rpy="1.5708 1.2605 0"/>
    <parent link="base_link"/>
    <child link="right_wheel"/>
    <axis xyz="0 0 1"/>
  </joint>

  <link name="camera">
    <inertial>
      <origin xyz="0 0 0" rpy="0 0 0"/>
      <mass value="0.1"/>
      <inertia ixx="0.0005" ixy="0.0" ixz="0.0"
               iyy="0.0005" iyz="0.0"
               izz="0.0005"/>
    </inertial>
    <visual>
      <origin xyz="0 0 0" rpy="0 0 0"/>
      <geometry>
        <mesh filename="package://matrix_bot/meshes/camera.STL"/>
      </geometry>
      <material name="">
        <color rgba="0.79 0.82 0.93 1"/>
      </material>
    </visual>
    <collision>
      <origin xyz="0 0 0" rpy="0 0 0"/>
      <geometry>
        <mesh filename="package://matrix_bot/meshes/camera.STL"/>
      </geometry>
    </collision>
  </link>

  <joint name="camera_joint" type="fixed">
    <origin xyz="-0.00222 -0.14781 0.13036" rpy="-1.5708 0 -3.1416"/>
    <parent link="base_link"/>
    <child link="camera"/>
    <axis xyz="0 0 0"/>
  </joint>

  <link name="imu_sensor">
    <inertial>
      <origin xyz="0 0 0" rpy="0 0 0"/>
      <mass value="0.1"/>
      <inertia ixx="0.0005" ixy="0.0" ixz="0.0"
               iyy="0.0005" iyz="0.0"
               izz="0.0005"/>
    </inertial>
    <visual>
      <origin xyz="0 0 0" rpy="0 0 0"/>
      <geometry>
        <mesh filename="package://matrix_bot/meshes/imu_sensor.STL"/>
      </geometry>
      <material name="">
        <color rgba="0.79 0.82 0.93 1"/>
      </material>
    </visual>
    <collision>
      <origin xyz="0 0 0" rpy="0 0 0"/>
      <geometry>
        <mesh filename="package://matrix_bot/meshes/imu_sensor.STL"/>
      </geometry>
    </collision>
  </link>

  <joint name="imu_sensor_joint" type="fixed">
    <origin xyz="0.16926 -0.14761 0.098569" rpy="1.5708 0.016066 0"/>
    <parent link="base_link"/>
    <child link="imu_sensor"/>
    <axis xyz="0 0 0"/>
  </joint>

  <link name="castor_wheel">
    <inertial>
      <origin xyz="0 0 0" rpy="0 0 0"/>
      <mass value="0.2"/>
      <inertia ixx="0.001" ixy="0.0" ixz="0.0"
               iyy="0.001" iyz="0.0"
               izz="0.001"/>
    </inertial>
    <visual>
      <origin xyz="0 0 0" rpy="0 0 0"/>
      <geometry>
        <mesh filename="package://matrix_bot/meshes/castor_wheel.STL"/>
      </geometry>
      <material name="">
        <color rgba="0.79 0.82 0.93 1"/>
      </material>
    </visual>
    <collision>
      <origin xyz="0 0 0" rpy="0 0 0"/>
      <geometry>
        <mesh filename="package://matrix_bot/meshes/castor_wheel.STL"/>
      </geometry>
    </collision>
  </link>

  <joint name="castor_wheel_joint" type="fixed">
    <origin xyz="0.02078 -0.11267 0.072307" rpy="2.6965 -0.45783 0.27225"/>
    <parent link="base_link"/>
    <child link="castor_wheel"/>
    <axis xyz="0 0 0"/>
  </joint>

  <link name="lidar_sensor">
    <inertial>
      <origin xyz="0 0 0" rpy="0 0 0"/>
      <mass value="0.1"/>
      <inertia ixx="0.0005" ixy="0.0" ixz="0.0"
               iyy="0.0005" iyz="0.0"
               izz="0.0005"/>
    </inertial>
    <visual>
      <origin xyz="0 0 0" rpy="0 0 0"/>
      <geometry>
        <mesh filename="package://matrix_bot/meshes/lidar_sensor.STL"/>
      </geometry>
      <material name="">
        <color rgba="0.79 0.82 0.93 1"/>
      </material>
    </visual>
    <collision>
      <origin xyz="0 0 0" rpy="0 0 0"/>
      <geometry>
        <mesh filename="package://matrix_bot/meshes/lidar_sensor.STL"/>
      </geometry>
    </collision>
  </link>

  <joint name="lidar_sensor_joint" type="fixed">
    <origin xyz="0.01278 -0.14761 0.14811" rpy="1.5708 0 0"/>
    <parent link="base_link"/>
    <child link="lidar_sensor"/>
    <axis xyz="0 0 0"/>
  </joint>
</robot>